<?xml version="1.0"?>
<robot name="DrSina">

    <gazebo>
        <plugin name="gazebo_ros_control" filename="libgazebo_ros_control.so">
                <robotNamespace>/drsina</robotNamespace>
                <!--robotSimType>gazebo_ros_control/DefaultRobotHWSim</robotSimType-->
                <legacyModeNS>true</legacyModeNS>
        </plugin>
    </gazebo>

<!--base and wheels-->
    <link name ="base_footprint"/>
    <link name="base_link">

        <visual>
            <origin rpy="0.0 0 0" xyz="0 0 0"/>
            <geometry>
                <mesh filename="package://drsina_description/models/meshes/chassis.dae"/>
            </geometry>
            <material name="grey"/>
        </visual>
        <collision>
             <origin rpy="0.0 0 0" xyz="0 0 0"/>
            <geometry>
                <mesh filename="package://drsina_description/models/meshes/chassis.dae"/>
            </geometry>
            <material name="grey"/>
        </collision>
        <inertial>
            <origin xyz="0.0 0.0 0.0" rpy="0.0 0.0 0.0"/>
            <mass value="28.798"/>
            <inertia ixx="15.17158" ixy="0.11133" ixz="-15.7747" iyy="1.61587" iyz="-10.583956" izz="1.3014955"/>
        </inertial>
        
	</link>

    <joint name="joint_name" type="fixed">
        <origin xyz="0.0 0.0 0.0" rpy="0.0 0.0 0.0"/>
        <parent link="base_footprint"/>
        <child link="base_link"/>
    </joint>

    <link name="Rwheel_link">
        <visual>
            <origin rpy="0 0 0" xyz="0.0 0.0 0.0"/>
            <geometry>
                <mesh filename="package://drsina_description/models/meshes/robotwheel.dae" />
            </geometry>
           
        </visual>
        <collision>
            <origin rpy="0 0 0" xyz="0.0 0.0 0.0"/>
            <geometry>
                <mesh filename="package://drsina_description/models/meshes/robotwheel.dae" />
            </geometry>
        </collision>
        <inertial>
            <origin xyz="0.0 0.0 0.0" rpy="0.0 0.0 0.0"/>
            <mass value="0.58215"/>
            <inertia ixx="0.0009071" ixy="0.0" ixz="0.0" iyy="0.000907" iyz="0.0" izz="0.00169379"/>
        </inertial>
        
    </link>

    <link name="Lwheel_link">

        <visual>
            <origin rpy="0 0 3.141592" xyz="0 0 0"/>
            <geometry>
                <mesh filename="package://drsina_description/models/meshes/robotwheel.dae" />
            </geometry>
            
        </visual>
        <collision>
            <origin rpy="0 0 3.141592" xyz="0 0 0"/>
            <geometry>
                <mesh filename="package://drsina_description/models/meshes/robotwheel.dae" />
            </geometry>
        </collision>
        <inertial>
            <origin rpy="0 0 3.141592" xyz="0 0 0"/>
            <mass value="0.58215"/>
            <inertia ixx="0.0009071" ixy="0.0" ixz="0.0" iyy="0.000907" iyz="0.0" izz="0.00169379"/>
        </inertial>
        
    </link>

    <joint name="roll_jointR" type="continuous">
    	<parent link="base_link"/>
    	<child link="Rwheel_link"/>
        <origin xyz="-0.0019 -0.235 -0.0239" rpy="0 0 0"/>
        <limit effort="100" velocity="100"/>
        <axis xyz="0 1 0"/>
	</joint>

    <joint name="roll_jointL" type="continuous">
    	<parent link="base_link"/>
    	<child link="Lwheel_link"/>
        <origin xyz="-0.0019 0.235 -0.0239" rpy="0 0 0"/>
        <limit effort="100" velocity="100"/>
        <axis xyz="0 1 0"/>
	</joint>


<!-- castle Wheel right Backward-->
    <link name="RBcastlewheel_link">

        <visual>
            <origin rpy="0 0 1.570796" xyz="-0.25761 -0.2065 0.027"/>
            <geometry>
                <mesh filename="package://drsina_description/models/meshes/topcastlewheel.dae" />
            </geometry>
        
        </visual>
        <collision>
            <origin rpy="0 0 1.570796" xyz="-0.25761 -0.2065 0.027"/>
            <geometry>
                <mesh filename="package://drsina_description/models/meshes/topcastlewheel.dae" />
            </geometry>
        </collision>
        <inertial>
            <origin rpy="0 0 1.570796" xyz="-0.25761 -0.2065 0.027"/>
            <mass value="0.12357"/>
            <inertia ixx="0.000127981" ixy="0.0" ixz="0.0" iyy="0.0002017879" iyz="0.0" izz="0.00007943143"/>
        </inertial>
    </link>

    <joint name="roll_jointcastleRB" type="fixed">
    	<parent link="base_link"/>
    	<child link="RBcastlewheel_link"/>
        <origin xyz="0.0 0 0.0" rpy="0 0 0"/>
	</joint>

    <link name="middlecastlewheelRB_link">

        <visual>
            <origin xyz="0.0 0 0.0" rpy="0 0 0"/>
            <!-- <origin rpy="0 0 1.570796" xyz="0 0 0"/> -->
            <geometry>
                <mesh filename="package://drsina_description/models/meshes/middlecastkewheel.dae" />
            </geometry>
        
        </visual>
        <collision>
            <origin xyz="0.0 0 0.0" rpy="0 0 0"/>
            <!-- <origin rpy="0 0 1.570796" xyz="0 0 0"/> -->
            <geometry>
                <mesh filename="package://drsina_description/models/meshes/middlecastkewheel.dae" />
            </geometry>
        
        </collision>
        <inertial>
            <origin xyz="0.0 0.0 0.0" rpy="0.0 0.0 0.0"/>
            <mass value="0.37662"/>
            <inertia ixx="0.00058885" ixy="0.000005035" ixz="0.0000023726" iyy="0.000391256" iyz="0.000171932" izz="0.000560966"/>
        </inertial>
        
    </link>

    <joint name="roll_jointmiddlecastleRB" type="continuous">
    	<parent link="RBcastlewheel_link"/>
    	<child link="middlecastlewheelRB_link"/>
        <origin rpy="0 0 1.570796" xyz="-0.25761 -0.2065 0.027"/>
        <limit effort="100" velocity="100"/>
        <axis xyz="0 0 1"/>
	</joint>

    <link name="castlewheel_wheelRBlink">

        <visual>
            <origin xyz="0.0 0 0.0" rpy="0 0 0"/>
            <geometry>
                <mesh filename="package://drsina_description/models/meshes/castlewheel.dae" />
            </geometry>
        
        </visual>
        <collision>
            <origin xyz="0.0 0 0.0" rpy="0 0 0"/>
            <geometry>
                <mesh filename="package://drsina_description/models/meshes/castlewheel.dae" />
            </geometry>
        
        </collision>
        <inertial>
            <origin xyz="0.0 0.0 0.0" rpy="0.0 0.0 0.0"/>
            <mass value="0.194"/>
            <inertia ixx="0.001469129" ixy="0.0" ixz="0.0" iyy="0.000363130" iyz="0.000468682" izz="0.001135254"/>
        </inertial>
        
    </link>

    <joint name="roll_jointcastlewheelRB" type="continuous">
    	<parent link="middlecastlewheelRB_link"/>
    	<child link="castlewheel_wheelRBlink"/>
        <!-- <origin rpy="0 0 1.570796" xyz="-0.2890 -0.2065 -0.048"/> -->
        <origin xyz="0 0.03239 -0.075" rpy="0 0 0"/>
        <limit effort="100" velocity="100"/>
        <axis xyz="1 0 0"/>
	</joint>

<!--  -->


<!-- castle Wheel right Forward-->
    <link name="RFcastlewheel_link">

        <visual>
            <origin rpy="0 0 1.570796" xyz="0.25761 -0.2065 0.027"/>
            <geometry>
                <mesh filename="package://drsina_description/models/meshes/topcastlewheel.dae" />
            </geometry>
        
        </visual>
        <collision>
            <origin rpy="0 0 1.570796" xyz="0.25761 -0.2065 0.027"/>
            <geometry>
                <mesh filename="package://drsina_description/models/meshes/topcastlewheel.dae" />
            </geometry>
        
        </collision>
        <inertial>
            <origin rpy="0 0 1.570796" xyz="0.25761 -0.2065 0.027"/>
            <mass value="0.12357"/>
            <inertia ixx="0.000127981" ixy="0.0" ixz="0.0" iyy="0.0002017879" iyz="0.0" izz="0.00007943143"/>
        </inertial>
        
    </link>

    <joint name="roll_jointcastleRF" type="fixed">
    	<parent link="base_link"/>
    	<child link="RFcastlewheel_link"/>
        <origin xyz="0.0 0 0.0" rpy="0 0 0"/>
	</joint>


    <link name="middlecastlewheelRF_link">

        <visual>
            <origin xyz="0.0 0 0.0" rpy="0 0 0"/>
            <geometry>
                <mesh filename="package://drsina_description/models/meshes/middlecastkewheel.dae" />
            </geometry>
        
        </visual>
        <collision>
            <origin xyz="0.0 0 0.0" rpy="0 0 0"/>
            <geometry>
                <mesh filename="package://drsina_description/models/meshes/middlecastkewheel.dae" />
            </geometry>
        </collision>
         <inertial>
            <origin xyz="0.0 0.0 0.0" rpy="0.0 0.0 0.0"/>
            <mass value="0.37662"/>
            <inertia ixx="0.00058885" ixy="0.000005035" ixz="0.0000023726" iyy="0.000391256" iyz="0.000171932" izz="0.000560966"/>
        </inertial>
        
    </link>

    <joint name="roll_jointmiddlecastleRF" type="continuous">
    	<parent link="RFcastlewheel_link"/>
    	<child link="middlecastlewheelRF_link"/>
        <origin rpy="0 0 1.570796" xyz="0.25761 -0.2065 0.027"/>
        <limit effort="100" velocity="100"/>
        <axis xyz="0 0 1"/>
	</joint>

    <link name="castlewheel_wheelRFlink">

        <visual>
            <origin xyz="0.0 0 0.0" rpy="0 0 0"/>
            <geometry>
                <mesh filename="package://drsina_description/models/meshes/castlewheel.dae" />
            </geometry>
        
        </visual>
        <collision>
            <origin xyz="0.0 0 0.0" rpy="0 0 0"/>
            <geometry>
                <mesh filename="package://drsina_description/models/meshes/castlewheel.dae" />
            </geometry>
        </collision>
        <inertial>
            <origin xyz="0.0 0.0 0.0" rpy="0.0 0.0 0.0"/>
            <mass value="0.194"/>
            <inertia ixx="0.001469129" ixy="0.0" ixz="0.0" iyy="0.000363130" iyz="0.000468682" izz="0.001135254"/>
        </inertial>
    </link>

    <joint name="roll_jointcastlewheelRF" type="continuous">
    	<parent link="middlecastlewheelRF_link"/>
    	<child link="castlewheel_wheelRFlink"/>
        <!-- <origin rpy="0 0 1.570796" xyz="0.2240 -0.2065 -0.048"/> -->
        <origin xyz="0 0.03239 -0.075" rpy="0 0 0"/>
        <limit effort="100" velocity="100"/>
        <axis xyz="1 0 0"/>
	</joint>
<!--  -->


<!-- castle Wheel Left Forward-->
    <link name="LFcastlewheel_link">

        <visual>
            <origin rpy="0 0 1.570796" xyz="0.25761 0.2065 0.027"/>
            <geometry>
                <mesh filename="package://drsina_description/models/meshes/topcastlewheel.dae" />
            </geometry>
        
        </visual>
        <collision>
            <origin rpy="0 0 1.570796" xyz="0.25761 0.2065 0.027"/>
            <geometry>
                <mesh filename="package://drsina_description/models/meshes/topcastlewheel.dae" />
            </geometry>
        
        </collision>
        <inertial>
            <origin rpy="0 0 1.570796" xyz="0.25761 0.2065 0.027"/>
            <mass value="0.12357"/>
            <inertia ixx="0.000127981" ixy="0.0" ixz="0.0" iyy="0.0002017879" iyz="0.0" izz="0.00007943143"/>
        </inertial>
    </link>

    <joint name="roll_jointcastleLF" type="fixed">
    	<parent link="base_link"/>
    	<child link="LFcastlewheel_link"/>
        <origin xyz="0.0 0 0.0" rpy="0 0 0"/>
	</joint>

    <link name="middlecastlewheelLF_link">

        <visual>
            <origin xyz="0.0 0 0.0" rpy="0 0 0"/>
            <geometry>
                <mesh filename="package://drsina_description/models/meshes/middlecastkewheel.dae" />
            </geometry>
        
        </visual>
        <collision>
            <origin xyz="0.0 0 0.0" rpy="0 0 0"/>
            <geometry>
                <mesh filename="package://drsina_description/models/meshes/middlecastkewheel.dae" />
            </geometry>
        </collision>
         <inertial>
            <origin xyz="0.0 0.0 0.0" rpy="0.0 0.0 0.0"/>
            <mass value="0.37662"/>
            <inertia ixx="0.00058885" ixy="0.000005035" ixz="0.0000023726" iyy="0.000391256" iyz="0.000171932" izz="0.000560966"/>
        </inertial>
        
    </link>

    <joint name="roll_jointmiddlecastleLF" type="continuous">
    	<parent link="LFcastlewheel_link"/>
    	<child link="middlecastlewheelLF_link"/>
        <origin rpy="0 0 1.570796" xyz="0.25761 0.2065 0.027"/>
        <limit effort="100" velocity="100"/>
        <axis xyz="0 0 1"/>
	</joint>

    <link name="castlewheel_wheelLFlink">

        <visual>
            <origin xyz="0.0 0 0.0" rpy="0 0 0"/>
            <geometry>
                <mesh filename="package://drsina_description/models/meshes/castlewheel.dae" />
            </geometry>

        </visual>
        <collision>
            <origin xyz="0.0 0 0.0" rpy="0 0 0"/>
            <geometry>
                <mesh filename="package://drsina_description/models/meshes/castlewheel.dae" />
            </geometry>

        </collision>
        <inertial>
            <origin xyz="0.0 0.0 0.0" rpy="0.0 0.0 0.0"/>
            <mass value="0.194"/>
            <inertia ixx="0.001469129" ixy="0.0" ixz="0.0" iyy="0.000363130" iyz="0.000468682" izz="0.001135254"/>
        </inertial>
    </link>

    <joint name="roll_jointcastlewheelLF" type="continuous">
    	<parent link="middlecastlewheelLF_link"/>
    	<child link="castlewheel_wheelLFlink"/>
        <origin  xyz="0 0.03239 -0.075" rpy="0 0 0"/>
        <limit effort="100" velocity="100"/>
        <axis xyz="1 0 0"/>
	</joint>
<!--  -->
    

<!-- castle Wheel Left Backward-->
    <link name="LBcastlewheel_link">

        <visual>
            <origin rpy="0 0 1.570796" xyz="-0.25761 0.2065 0.027"/>
            <geometry>
                <mesh filename="package://drsina_description/models/meshes/topcastlewheel.dae" />
            </geometry>
        
        </visual>
        <collision>
            <origin rpy="0 0 1.570796" xyz="-0.25761 0.2065 0.027"/>
            <geometry>
                <mesh filename="package://drsina_description/models/meshes/topcastlewheel.dae" />
            </geometry>
        
        </collision>
        <inertial>
            <origin rpy="0 0 1.570796" xyz="-0.25761 0.2065 0.027"/>
            <mass value="0.12357"/>
            <inertia ixx="0.000127981" ixy="0.0" ixz="0.0" iyy="0.0002017879" iyz="0.0" izz="0.00007943143"/>
        </inertial>
    </link>

    <joint name="roll_jointcastleLB" type="fixed">
    	<parent link="base_link"/>
    	<child link="LBcastlewheel_link"/>
        <origin xyz="0.0 0 0.0" rpy="0 0 0"/>
	</joint>
 
    <link name="middlecastlewheelLB_link">

        <visual>
            <origin xyz="0.0 0 0.0" rpy="0 0 0"/>
            <geometry>
                <mesh filename="package://drsina_description/models/meshes/middlecastkewheel.dae" />
            </geometry>
        
        </visual>
        <collision>
            <origin xyz="0.0 0 0.0" rpy="0 0 0"/>
            <geometry>
                <mesh filename="package://drsina_description/models/meshes/middlecastkewheel.dae" />
            </geometry>
        
        </collision>
         <inertial>
            <origin xyz="0.0 0.0 0.0" rpy="0.0 0.0 0.0"/>
            <mass value="0.37662"/>
            <inertia ixx="0.00058885" ixy="0.000005035" ixz="0.0000023726" iyy="0.000391256" iyz="0.000171932" izz="0.000560966"/>
        </inertial>
        
    </link>

    <joint name="roll_jointmiddlecastleLB" type="continuous">
    	<parent link="LBcastlewheel_link"/>
    	<child link="middlecastlewheelLB_link"/>
        <origin rpy="0 0 1.570796" xyz="-0.25761 0.2065 0.027"/>
        <limit effort="100" velocity="100"/>
        <axis xyz="0 0 1"/>
	</joint>

    <link name="castlewheel_wheelLBlink">

        <visual>
            <origin xyz="0.0 0 0.0" rpy="0 0 0"/>
            <geometry>
                <mesh filename="package://drsina_description/models/meshes/castlewheel.dae" />
            </geometry>
        
        </visual>
        <collision>
            <origin xyz="0.0 0 0.0" rpy="0 0 0"/>
            <geometry>
                <mesh filename="package://drsina_description/models/meshes/castlewheel.dae" />
            </geometry>
        
        </collision>
        <inertial>
            <origin xyz="0.0 0.0 0.0" rpy="0.0 0.0 0.0"/>
            <mass value="0.194"/>
            <inertia ixx="0.001469129" ixy="0.0" ixz="0.0" iyy="0.000363130" iyz="0.000468682" izz="0.001135254"/>
        </inertial>
    </link>

    <joint name="roll_jointcastlewheelLB" type="continuous">
    	<parent link="middlecastlewheelLB_link"/>
    	<child link="castlewheel_wheelLBlink"/>
        <origin xyz="0 0.03239 -0.075" rpy="0 0 0"/>
        <limit effort="100" velocity="100"/>
        <axis xyz="1 0 0"/>
	</joint>
<!--  -->

<!-- Light indicator -->

    <link name="emergencyButton_link">

        <visual>
            <origin rpy="0 -1.570796 0" xyz="-0.360 0 0"/>
            <geometry>
                <mesh filename="package://drsina_description/models/meshes/emergencyButton.dae" />
            </geometry>
        
        </visual>
        <collision>
            <origin rpy="0 -1.570796 0" xyz="-0.360 0 0"/>
            <geometry>
                <mesh filename="package://drsina_description/models/meshes/emergencyButton.dae" />
            </geometry>
        
        </collision>
        <inertial>
            <origin rpy="0 -1.570796 0" xyz="-0.360 0 0"/>
            <mass value="0.024"/>
            <inertia ixx="0.000014158" ixy="0.0" ixz="0.0" iyy="0.000014218" iyz="0.000001560" izz="0.000004097"/>
        </inertial>
        
    </link>

    <joint name="emergencyButton_joint" type="fixed">
    	<parent link="base_link"/>
    	<child link="emergencyButton_link"/>
        <origin xyz="0 0 0" rpy="0 0 0"/>
	</joint>


    <link name="yellowligthR_link">

        <visual>
            <origin rpy="0 -1.570796 0" xyz="-0.365 0.158 0"/>
            <geometry>
                <mesh filename="package://drsina_description/models/meshes/lightback.dae" />
            </geometry>
        
        </visual>
        <collision>
            <origin rpy="0 -1.570796 0" xyz="-0.365 0.158 0"/>
            <geometry>
                <mesh filename="package://drsina_description/models/meshes/lightback.dae" />
            </geometry>
        
        </collision>
        <inertial>
            <origin rpy="0 -1.570796 0" xyz="-0.365 0.158 0"/>
            <mass value="0.013"/>
            <inertia ixx="0.000001335" ixy="0.0" ixz="0.0" iyy="0.000001112" iyz="0.0" izz="0.000001335"/>
        </inertial>
        
    </link>

    <joint name="yellowligthR_joint" type="fixed">
    	<parent link="base_link"/>
    	<child link="yellowligthR_link"/>
        <origin xyz="0 0 0" rpy="0 0 0"/>  
	</joint>

    <link name="yellowligthL_link">

        <visual>
            <origin rpy="0 -1.570796 0" xyz="-0.365 -0.158 0"/>
            <geometry>
                <mesh filename="package://drsina_description/models/meshes/lightback.dae" />
            </geometry>
        
        </visual>
        <collision>
            <origin rpy="0 -1.570796 0" xyz="-0.365 -0.158 0"/>
            <geometry>
                <mesh filename="package://drsina_description/models/meshes/lightback.dae" />
            </geometry>
        
        </collision>
        <inertial>
            <origin rpy="0 -1.570796 0" xyz="-0.365 -0.158 0"/>
            <mass value="0.013"/>
            <inertia ixx="0.000001335" ixy="0.0" ixz="0.0" iyy="0.000001112" iyz="0.0" izz="0.000001335"/>
        </inertial>
        
    </link>

    <joint name="yellowligthL_joint" type="fixed">
    	<parent link="base_link"/>
    	<child link="yellowligthL_link"/>
        <origin xyz="0 0 0" rpy="0 0 0"/>  
	</joint>


    <link name="redligthR_link">

        <visual>
            <origin rpy="0 -1.570796 0" xyz="-0.365 0.095 0"/>
            <geometry>
                <mesh filename="package://drsina_description/models/meshes/lightbackRed.dae" />
            </geometry>
        
        </visual>
        <collision>
            <origin rpy="0 -1.570796 0" xyz="-0.365 0.095 0"/>
            <geometry>
                <mesh filename="package://drsina_description/models/meshes/lightbackRed.dae" />
            </geometry>
        
        </collision>
        <inertial>
            <origin rpy="0 -1.570796 0" xyz="-0.365 0.095 0"/>
            <mass value="0.013"/>
            <inertia ixx="0.000001335" ixy="0.0" ixz="0.0" iyy="0.000001112" iyz="0.0" izz="0.000001335"/>
        </inertial>
    </link>

    <joint name="redligthR_joint" type="fixed">
    	<parent link="base_link"/>
    	<child link="redligthR_link"/>
        <origin xyz="0 0 0" rpy="0 0 0"/>  
	</joint>

    <link name="redligthL_link">

        <visual>
            <origin rpy="0 -1.570796 0" xyz="-0.365 -0.095 0"/>
            <geometry>
                <mesh filename="package://drsina_description/models/meshes/lightbackRed.dae" />
            </geometry>
        
        </visual>
        <collision>
            <origin rpy="0 -1.570796 0" xyz="-0.365 -0.095 0"/>
            <geometry>
                <mesh filename="package://drsina_description/models/meshes/lightbackRed.dae" />
            </geometry>
        
        </collision>
        <inertial>
            <origin rpy="0 -1.570796 0" xyz="-0.365 -0.095 0"/>
            <mass value="0.013"/>
            <inertia ixx="0.000001335" ixy="0.0" ixz="0.0" iyy="0.000001112" iyz="0.0" izz="0.000001335"/>
        </inertial>
    </link>

    <joint name="redligthL_joint" type="fixed">
    	<parent link="base_link"/>
    	<child link="redligthL_link"/>
        <origin xyz="0 0 0" rpy="0 0 0"/>  
	</joint>

<!--  -->

<!-- green button -->
    <link name="greenButton_link">

        <visual>
            <origin rpy="0 0 0" xyz="0.298 0.1001 0.075"/>
            <geometry>
                <mesh filename="package://drsina_description/models/meshes/buttongreen.dae" />
            </geometry>
        
        </visual>
        <collision>
            <origin rpy="0 0 0" xyz="0.298 0.1001 0.075"/>
            <geometry>
                <mesh filename="package://drsina_description/models/meshes/buttongreen.dae" />
            </geometry>
        
        </collision>
        <inertial>
            <origin rpy="0 0 0" xyz="0.298 0.1001 0.075"/>
            <mass value="0.009"/>
            <inertia ixx="0.000048877" ixy="0.000004137" ixz="0.000007347" iyy="0.000039205" iyz="0.000019882" izz="0.000013807"/>
        </inertial>
    </link>

    <joint name="greenButton_joint" type="fixed">
    	<parent link="base_link"/>
    	<child link="greenButton_link"/>
        <origin xyz="0 0 0" rpy="0 0 0"/>  
	</joint>
<!--  -->

<!-- red Button -->
    <link name="redButton_link">

        <visual>
            <origin rpy="0 0 0" xyz="0.298 -0.1001 0.075"/>
            <geometry>
                <mesh filename="package://drsina_description/models/meshes/buttonred.dae" />
            </geometry>
        
        </visual>
        <collision>
            <origin rpy="0 0 0" xyz="0.298 -0.1001 0.075"/>
            <geometry>
                <mesh filename="package://drsina_description/models/meshes/buttonred.dae" />
            </geometry>
        
        </collision>
        <inertial>
            <origin rpy="0 0 0" xyz="0.298 -0.1001 0.075"/>
            <mass value="0.009"/>
            <inertia ixx="0.000048877" ixy="0.000004137" ixz="0.000007347" iyy="0.000039205" iyz="0.000019882" izz="0.000013807"/>
        </inertial>
    </link>

    <joint name="redButton_joint" type="fixed">
    	<parent link="base_link"/>
    	<child link="redButton_link"/>
        <origin xyz="0 0 0" rpy="0 0 0"/>  
	</joint>
<!--  -->

<!-- lidar  -->
    <link name="lidar_link">

        <visual>
            <origin rpy="0 0 0" xyz="0.303 -0.006 0.1"/>
            <geometry>
                <mesh filename="package://drsina_description/models/meshes/lidar.dae" />
            </geometry>
        
        </visual>
        <collision>
            <origin rpy="0 0 0" xyz="0.303 -0.006 0.1"/>
            <geometry>
                <mesh filename="package://drsina_description/models/meshes/lidar.dae" />
            </geometry>
        
        </collision>
        <inertial>
            <origin xyz="0.0 0.0 0.0" rpy="0.0 0.0 0.0"/>
            <mass value="0.073"/>
            <inertia ixx="0.0418344" ixy="-0.00427706" ixz="-0.000766149" iyy="0.001823843" iyz="0.007260811" izz="0.041013051"/>
        </inertial>
        
    </link>

    <joint name="lidar_joint" type="fixed">
    	<parent link="base_link"/>
    	<child link="lidar_link"/>
        <origin xyz="0 0 0" rpy="0 0 0"/>  
	</joint>
<!--  -->

<!--gazbo config-->   
      <gazebo reference="Rwheel_link">
	    <mu1>20000000000.0</mu1>
	    <mu2>20000000000.0</mu2>
	    <kp>1000000.0</kp>
	    <kd>1.0</kd>
	  </gazebo>
	
	  <gazebo reference="Lwheel_link">
	    <mu1>20000000000.0</mu1>
	    <mu2>20000000000.0</mu2>
	    <kp>1000000.0</kp>
	    <kd>1.0</kd>
	  </gazebo>
	  
	  <gazebo reference="roll_jointcastlewheelRF">
	    <mu1>1.0</mu1>
	    <mu2>1.0</mu2>
	    <kp>1000000.0</kp>
	    <kd>100.0</kd>
	  </gazebo>
	  
	  <gazebo reference="roll_jointcastlewheelLF">
	    <mu1>1.0</mu1>
	    <mu2>1.0</mu2>
	    <kp>1000000.0</kp>
	    <kd>100.0</kd>
	  </gazebo>
      <gazebo reference="roll_jointcastlewheelRB">
	    <mu1>1.0</mu1>
	    <mu2>1.0</mu2>
	    <kp>1000000.0</kp>
	    <kd>100.0</kd>
	  </gazebo>
	  
	  <gazebo reference="roll_jointcastlewheelLB">
	    <mu1>1.0</mu1>
	    <mu2>1.0</mu2>
	    <kp>1000000.0</kp>
	    <kd>100.0</kd>
	  </gazebo>
<!--transmissions-->
    <transmission name="left_wheel_transmission">
        <type>transmission_interface/SimpleTransmission</type>
        <joint name="roll_jointL">
            <hardwareInterface>hardware_interface/VelocityJointInterface</hardwareInterface>  
        </joint>
        <actuator name="left_wheel_actuator">
            <mechanicalReduction>7</mechanicalReduction>
            <hardwareInterface>hardware_interface/VelocityJointInterface</hardwareInterface>
        </actuator>
    </transmission>
    
    <transmission name="right_wheel_transmission">
        <type>transmission_interface/SimpleTransmission</type>
        <joint name="roll_jointR">
            <hardwareInterface>hardware_interface/VelocityJointInterface</hardwareInterface>  
        </joint>
        <actuator name="right_wheel_actuator">
            <mechanicalReduction>7</mechanicalReduction>
            <hardwareInterface>hardware_interface/VelocityJointInterface</hardwareInterface>
        </actuator>
    </transmission>


</robot>