<?xml version="1.0"?>
<robot name="robot" xmlns:xacro="http://www.ros.org/wiki/xacro">
     <material name="black">
        <color rgba="0.0 0.0 0.0 1.0" />
    </material>
    <material name="navy">
        <color rgba="0.0 0.0 128.0 1.0" />
    </material>
    <material name="cyan">
        <color rgba="0.0 255.0 255.0 1.0" />
    </material>
    <material name="silver">
        <color rgba="150.0 150.0 150.0 1.0" />
    </material>
    <material name="silverT">
        <color rgba="150.0 150.0 150.0 0.7" />
    </material>
    <material name="argent">
        <color rgba="206.0 206.0 206.0 1.0" />
    </material>
    <material name="red">
        <color rgba="255.0 0.0  0.0 1.0" />
    </material>
    <material name="blue">
        <color rgba="0.0 0.0  255.0 1.0" />
    </material>

    <link name="base_link">

        <visual>
            <origin rpy="0.0 0 0" xyz="0 0 0"/>
            <geometry>
                <mesh filename="package://hospital_robot/meshes/chassis.dae"/>
            </geometry>
            <material name="grey"/>
        </visual>
	</link>

    <link name="Rwheel_link">
        <visual>
            <origin rpy="0 0 0" xyz="0.0 0.0 0.0"/>
            <geometry>
                <mesh filename="package://hospital_robot/meshes/robotwheel.dae" />
            </geometry>
           
        </visual>
    </link>

    <link name="Lwheel_link">

        <visual>
            <origin rpy="0 0 3.141592" xyz="0 0 0"/>
            <geometry>
                <mesh filename="package://hospital_robot/meshes/robotwheel.dae" />
            </geometry>
            
        </visual>
    </link>

    <joint name="roll_jointR" type="continuous">
    	<parent link="base_link"/>
    	<child link="Rwheel_link"/>
        <origin xyz="-0.0019 -0.235 -0.0239" rpy="0 0 0"/>
        <limit effort="100" velocity="100"/>
        <axis xyz="0 1 0"/>
	</joint>

    <joint name="roll_jointL" type="continuous">
    	<parent link="base_link"/>
    	<child link="Lwheel_link"/>
        <origin xyz="-0.0019 0.235 -0.0239" rpy="0 0 0"/>
        <limit effort="100" velocity="100"/>
        <axis xyz="0 1 0"/>
	</joint>


<!-- castle Wheel right Backward-->
    <link name="RBcastlewheel_link">

        <visual>
            <origin rpy="0 0 1.570796" xyz="-0.25761 -0.2065 0.027"/>
            <geometry>
                <mesh filename="package://hospital_robot/meshes/topcastlewheel.dae" />
            </geometry>
        
        </visual>
    </link>

    <joint name="roll_jointcastleRB" type="fixed">
    	<parent link="base_link"/>
    	<child link="RBcastlewheel_link"/>
        <origin xyz="0.0 0 0.0" rpy="0 0 0"/>
	</joint>

    <link name="middlecastlewheelRB_link">

        <visual>
            <origin xyz="0.0 0 0.0" rpy="0 0 0"/>
            <!-- <origin rpy="0 0 1.570796" xyz="0 0 0"/> -->
            <geometry>
                <mesh filename="package://hospital_robot/meshes/middlecastkewheel.dae" />
            </geometry>
        
        </visual>
    </link>

    <joint name="roll_jointmiddlecastleRB" type="continuous">
    	<parent link="RBcastlewheel_link"/>
    	<child link="middlecastlewheelRB_link"/>
        <origin rpy="0 0 1.570796" xyz="-0.25761 -0.2065 0.027"/>
        <limit effort="100" velocity="100"/>
        <axis xyz="0 0 1"/>
	</joint>

    <link name="castlewheel_wheelRBlink">

        <visual>
            <origin xyz="0.0 0 0.0" rpy="0 0 0"/>
            <geometry>
                <mesh filename="package://hospital_robot/meshes/castlewheel.dae" />
            </geometry>
        
        </visual>
    </link>

    <joint name="roll_jointcastlewheelRB" type="continuous">
    	<parent link="middlecastlewheelRB_link"/>
    	<child link="castlewheel_wheelRBlink"/>
        <!-- <origin rpy="0 0 1.570796" xyz="-0.2890 -0.2065 -0.048"/> -->
        <origin xyz="0 0.03239 -0.075" rpy="0 0 0"/>
        <limit effort="100" velocity="100"/>
        <axis xyz="1 0 0"/>
	</joint>

<!--  -->


<!-- castle Wheel right Forward-->
    <link name="RFcastlewheel_link">

        <visual>
            <origin rpy="0 0 1.570796" xyz="0.25761 -0.2065 0.027"/>
            <geometry>
                <mesh filename="package://hospital_robot/meshes/topcastlewheel.dae" />
            </geometry>
        
        </visual>
    </link>

    <joint name="roll_jointcastleRF" type="fixed">
    	<parent link="base_link"/>
    	<child link="RFcastlewheel_link"/>
        <origin xyz="0.0 0 0.0" rpy="0 0 0"/>
	</joint>


    <link name="middlecastlewheelRF_link">

        <visual>
            <origin xyz="0.0 0 0.0" rpy="0 0 0"/>
            <geometry>
                <mesh filename="package://hospital_robot/meshes/middlecastkewheel.dae" />
            </geometry>
        
        </visual>
    </link>

    <joint name="roll_jointmiddlecastleRF" type="continuous">
    	<parent link="RFcastlewheel_link"/>
    	<child link="middlecastlewheelRF_link"/>
        <origin rpy="0 0 1.570796" xyz="0.25761 -0.2065 0.027"/>
        <limit effort="100" velocity="100"/>
        <axis xyz="0 0 1"/>
	</joint>

    <link name="castlewheel_wheelRFlink">

        <visual>
            <origin xyz="0.0 0 0.0" rpy="0 0 0"/>
            <geometry>
                <mesh filename="package://hospital_robot/meshes/castlewheel.dae" />
            </geometry>
        
        </visual>
    </link>

    <joint name="roll_jointcastlewheelRF" type="continuous">
    	<parent link="middlecastlewheelRF_link"/>
    	<child link="castlewheel_wheelRFlink"/>
        <!-- <origin rpy="0 0 1.570796" xyz="0.2240 -0.2065 -0.048"/> -->
        <origin xyz="0 0.03239 -0.075" rpy="0 0 0"/>
        <limit effort="100" velocity="100"/>
        <axis xyz="1 0 0"/>
	</joint>
<!--  -->


<!-- castle Wheel Left Forward-->
    <link name="LFcastlewheel_link">

        <visual>
            <origin rpy="0 0 1.570796" xyz="0.25761 0.2065 0.027"/>
            <geometry>
                <mesh filename="package://hospital_robot/meshes/topcastlewheel.dae" />
            </geometry>
        
        </visual>
    </link>

    <joint name="roll_jointcastleLF" type="fixed">
    	<parent link="base_link"/>
    	<child link="LFcastlewheel_link"/>
        <origin xyz="0.0 0 0.0" rpy="0 0 0"/>
	</joint>

    <link name="middlecastlewheelLF_link">

        <visual>
            <origin xyz="0.0 0 0.0" rpy="0 0 0"/>
            <geometry>
                <mesh filename="package://hospital_robot/meshes/middlecastkewheel.dae" />
            </geometry>
        
        </visual>
    </link>

    <joint name="roll_jointmiddlecastleLF" type="continuous">
    	<parent link="LFcastlewheel_link"/>
    	<child link="middlecastlewheelLF_link"/>
        <origin rpy="0 0 1.570796" xyz="0.25761 0.2065 0.027"/>
        <limit effort="100" velocity="100"/>
        <axis xyz="0 0 1"/>
	</joint>

    <link name="castlewheel_wheelLFlink">

        <visual>
            <origin xyz="0.0 0 0.0" rpy="0 0 0"/>
            <geometry>
                <mesh filename="package://hospital_robot/meshes/castlewheel.dae" />
            </geometry>

        </visual>
    </link>

    <joint name="roll_jointcastlewheelLF" type="continuous">
    	<parent link="middlecastlewheelLF_link"/>
    	<child link="castlewheel_wheelLFlink"/>
        <origin  xyz="0 0.03239 -0.075" rpy="0 0 0"/>
        <limit effort="100" velocity="100"/>
        <axis xyz="1 0 0"/>
	</joint>
<!--  -->
    

<!-- castle Wheel Left Backward-->
    <link name="LBcastlewheel_link">

        <visual>
            <origin rpy="0 0 1.570796" xyz="-0.25761 0.2065 0.027"/>
            <geometry>
                <mesh filename="package://hospital_robot/meshes/topcastlewheel.dae" />
            </geometry>
        
        </visual>
    </link>

    <joint name="roll_jointcastleLB" type="fixed">
    	<parent link="base_link"/>
    	<child link="LBcastlewheel_link"/>
        <origin xyz="0.0 0 0.0" rpy="0 0 0"/>
	</joint>
 
    <link name="middlecastlewheelLB_link">

        <visual>
            <origin xyz="0.0 0 0.0" rpy="0 0 0"/>
            <geometry>
                <mesh filename="package://hospital_robot/meshes/middlecastkewheel.dae" />
            </geometry>
        
        </visual>
    </link>

    <joint name="roll_jointmiddlecastleLB" type="continuous">
    	<parent link="LBcastlewheel_link"/>
    	<child link="middlecastlewheelLB_link"/>
        <origin rpy="0 0 1.570796" xyz="-0.25761 0.2065 0.027"/>
        <limit effort="100" velocity="100"/>
        <axis xyz="0 0 1"/>
	</joint>

    <link name="castlewheel_wheelLBlink">

        <visual>
            <origin xyz="0.0 0 0.0" rpy="0 0 0"/>
            <geometry>
                <mesh filename="package://hospital_robot/meshes/castlewheel.dae" />
            </geometry>
        
        </visual>
    </link>

    <joint name="roll_jointcastlewheelLB" type="continuous">
    	<parent link="middlecastlewheelLB_link"/>
    	<child link="castlewheel_wheelLBlink"/>
        <origin xyz="0 0.03239 -0.075" rpy="0 0 0"/>
        <limit effort="100" velocity="100"/>
        <axis xyz="1 0 0"/>
	</joint>
<!--  -->

<!-- Light indicator -->

    <link name="emergencyButton_link">

        <visual>
            <origin rpy="0 -1.570796 0" xyz="-0.360 0 0"/>
            <geometry>
                <mesh filename="package://hospital_robot/meshes/emergencyButton.dae" />
            </geometry>
        
        </visual>
    </link>

    <joint name="emergencyButton_joint" type="fixed">
    	<parent link="base_link"/>
    	<child link="emergencyButton_link"/>
        <origin xyz="0 0 0" rpy="0 0 0"/>
	</joint>


    <link name="yellowligthR_link">

        <visual>
            <origin rpy="0 -1.570796 0" xyz="-0.365 0.158 0"/>
            <geometry>
                <mesh filename="package://hospital_robot/meshes/lightback.dae" />
            </geometry>
        
        </visual>
    </link>

    <joint name="yellowligthR_joint" type="fixed">
    	<parent link="base_link"/>
    	<child link="yellowligthR_link"/>
        <origin xyz="0 0 0" rpy="0 0 0"/>  
	</joint>

    <link name="yellowligthL_link">

        <visual>
            <origin rpy="0 -1.570796 0" xyz="-0.365 -0.158 0"/>
            <geometry>
                <mesh filename="package://hospital_robot/meshes/lightback.dae" />
            </geometry>
        
        </visual>
    </link>

    <joint name="yellowligthL_joint" type="fixed">
    	<parent link="base_link"/>
    	<child link="yellowligthL_link"/>
        <origin xyz="0 0 0" rpy="0 0 0"/>  
	</joint>


    <link name="redligthR_link">

        <visual>
            <origin rpy="0 -1.570796 0" xyz="-0.365 0.095 0"/>
            <geometry>
                <mesh filename="package://hospital_robot/meshes/lightbackRed.dae" />
            </geometry>
        
        </visual>
    </link>

    <joint name="redligthR_joint" type="fixed">
    	<parent link="base_link"/>
    	<child link="redligthR_link"/>
        <origin xyz="0 0 0" rpy="0 0 0"/>  
	</joint>

    <link name="redligthL_link">

        <visual>
            <origin rpy="0 -1.570796 0" xyz="-0.365 -0.095 0"/>
            <geometry>
                <mesh filename="package://hospital_robot/meshes/lightbackRed.dae" />
            </geometry>
        
        </visual>
    </link>

    <joint name="redligthL_joint" type="fixed">
    	<parent link="base_link"/>
    	<child link="redligthL_link"/>
        <origin xyz="0 0 0" rpy="0 0 0"/>  
	</joint>

<!--  -->

<!-- green button -->
    <link name="greenButton_link">

        <visual>
            <origin rpy="0 0 0" xyz="0.298 0.1001 0.075"/>
            <geometry>
                <mesh filename="package://hospital_robot/meshes/buttongreen.dae" />
            </geometry>
        
        </visual>
    </link>

    <joint name="greenButton_joint" type="fixed">
    	<parent link="base_link"/>
    	<child link="greenButton_link"/>
        <origin xyz="0 0 0" rpy="0 0 0"/>  
	</joint>
<!--  -->

<!-- red Button -->
    <link name="redButton_link">

        <visual>
            <origin rpy="0 0 0" xyz="0.298 -0.1001 0.075"/>
            <geometry>
                <mesh filename="package://hospital_robot/meshes/buttonred.dae" />
            </geometry>
        
        </visual>
    </link>

    <joint name="redButton_joint" type="fixed">
    	<parent link="base_link"/>
    	<child link="redButton_link"/>
        <origin xyz="0 0 0" rpy="0 0 0"/>  
	</joint>
<!--  -->

<!-- lidar  -->
    <link name="lidar_link">

        <visual>
            <origin rpy="0 0 0" xyz="0.303 -0.006 0.1"/>
            <geometry>
                <mesh filename="package://hospital_robot/meshes/lidar.dae" />
            </geometry>
        
        </visual>
    </link>

    <joint name="lidar_joint" type="fixed">
    	<parent link="base_link"/>
    	<child link="lidar_link"/>
        <origin xyz="0 0 0" rpy="0 0 0"/>  
	</joint>
<!--  -->
<!-- base armoire link  -->
    <link name="fix">
     <pose>0 0 0 0 0 0</pose>
        <inertial>
            <origin xyz="0 0 0" rpy="0 0 0" />
            <mass value="40" />
            <inertia
                ixx="0.732368148523831"
                ixy="1.11340514515552E-06"
                ixz="2.11680638683535E-18"
                iyy="0.677204899068401"
                iyz="-2.63878968453045E-08"
                izz="1.4091545109818" />
            </inertial>

        <collision>
            <origin xyz="0 0 0" rpy="1.57 0 0" />
            <geometry>
                <mesh filename="package://hospital_robot/meshes/fix.stl" />
            </geometry>
        </collision>

        <visual>
            <origin xyz="0 0 0" rpy="1.57 0 0" />
            <geometry>
                <mesh
                filename="package://hospital_robot/meshes/fix.stl" />
            </geometry>
            <material name="silver"/>
        </visual>
    </link>

    <joint name="principle_joint" type="fixed">
        <origin xyz="-0.3 0 0.19" rpy="0 0 0" />
    	<parent link="base_link"/>
    	<child link="fix"/>
        <origin xyz="0 0 0" rpy="0 0 0"/>  
	</joint>
<!--  -->

    <link name="lampe">
     <pose>0 0 0 0 0 0</pose>
        <inertial>
            <origin xyz="0 0 0" rpy="0 0 0" />
            <mass value="0.2" />
            <inertia
                ixx="0.732368148523831"
                ixy="1.11340514515552E-06"
                ixz="2.11680638683535E-18"
                iyy="0.677204899068401"
                iyz="-2.63878968453045E-08"
                izz="1.4091545109818" />
            </inertial>

        <collision>
            <origin xyz="0 0 0" rpy="0 0 1.57" />
            <geometry>
                <mesh filename="package://hospital_robot/meshes/lampe.stl" />
            </geometry>
        </collision>

        <visual>
            <origin xyz="0 0 0" rpy="0 0 1.57" />
            <geometry>
                <mesh
                filename="package://hospital_robot/meshes/lampe.stl" />
            </geometry>
            <material name="red"/>
        </visual>
    </link>

  <joint name="lampe_joint" type="fixed">
    <origin xyz="0.2 -0.05 1.01" rpy="0 0 0" />
    <parent link="fix" />
    <child link="lampe" />
    <axis xyz="0 0 0" />
  </joint>


  <link name="sep1">
     <pose>0 0 0 0 0 0</pose>

        <collision>
            <origin xyz="0 0 0" rpy="0 0 3.14" />
            <geometry>
                <mesh filename="package://hospital_robot/meshes/sep_complexe.stl" />
            </geometry>
        </collision>

        <visual>
            <origin xyz="0 0 0" rpy="0 0 3.14" />
            <geometry>
                <mesh
                filename="package://hospital_robot/meshes/sep_complexe.stl" />
            </geometry>
            <material name="cyan"/>
        </visual>
    </link>

    <joint name="sep1_joint" type="fixed">
    <origin xyz="0.345 0.21 0.01" rpy="0 0 0" />
    <parent link="fix" />
    <child link="sep1" />
    <axis xyz="0 0 0" />
  </joint>

  <link name="sep2">
     <pose>0 0 0 0 0 0</pose>

        <collision>
            <origin xyz="0 0 0" rpy="0 0 1.57" />
            <geometry>
                <mesh filename="package://hospital_robot/meshes/sep_simple.stl" />
            </geometry>
        </collision>

        <visual>
            <origin xyz="0 0 0" rpy="0 0 1.57" />
            <geometry>
                <mesh
                filename="package://hospital_robot/meshes/sep_simple.stl" />
            </geometry>
            <material name="cyan"/>
        </visual>
    </link>

    <joint name="sep2_joint" type="fixed">
    <origin xyz="0.25 0.15 0.01" rpy="0 0 0" />
    <parent link="fix" />
    <child link="sep2" />
    <axis xyz="0 0 0" />
  </joint>

  <link name="sep1.2">
     <pose>0 0 0 0 0 0</pose>

        <collision>
            <origin xyz="0 0 0" rpy="0 0 0" />
            <geometry>
                <mesh filename="package://hospital_robot/meshes/sep_complexe.stl" />
            </geometry>
        </collision>

        <visual>
            <origin xyz="0 0 0" rpy="0 0 0" />
            <geometry>
                <mesh
                filename="package://hospital_robot/meshes/sep_complexe.stl" />
            </geometry>
            <material name="cyan"/>
        </visual>
    </link>

    <joint name="sep1.2_joint" type="fixed">
    <origin xyz="0.07 -0.21 0.01" rpy="0 0 0" />
    <parent link="fix" />
    <child link="sep1.2" />
    <axis xyz="0 0 0" />
  </joint>

  <link name="sep2.2">
     <pose>0 0 0 0 0 0</pose>

        <collision>
            <origin xyz="0 0 0" rpy="0 0 1.57" />
            <geometry>
                <mesh filename="package://hospital_robot/meshes/sep_simple.stl" />
            </geometry>
        </collision>

        <visual>
            <origin xyz="0 0 0" rpy="0 0 1.57" />
            <geometry>
                <mesh
                filename="package://hospital_robot/meshes/sep_simple.stl" />
            </geometry>
            <material name="cyan"/>
        </visual>
    </link>

    <joint name="sep2.2_joint" type="fixed">
    <origin xyz="0.255 -0.28 0.01" rpy="0 0 0" />
    <parent link="fix" />
    <child link="sep2.2" />
    <axis xyz="0 0 0" />
  </joint>

  <link name="montechargeL">
     <pose>0 0 0 0 0 0</pose>

        <collision>
            <origin xyz="0 0 0" rpy="0 0 0" />
            <geometry>
                <mesh filename="package://hospital_robot/meshes/monteChargeL.stl" />
            </geometry>
        </collision>

        <visual>
            <origin xyz="0 0 0" rpy="0 0 0" />
            <geometry>
                <mesh
                filename="package://hospital_robot/meshes/monteChargeL.stl" />
            </geometry>
            <material name="black"/>
        </visual>
    </link>

    <joint name="mchL_joint" type="prismatic">
    <origin xyz="-0.315 -0.17 0" rpy="0 0 0" />
    <parent link="sep1" />
    <child link="montechargeL" />
    <axis xyz="0 0 1" />
    <limit effort="1000.0" lower="0.35" upper="1.0" velocity="0.5"/>
  </joint>

  <link name="montechargeR">
     <pose>0 0 0 0 0 0</pose>

        <collision>
            <origin xyz="0 0 0" rpy="3.14 0 0" />
            <geometry>
                <mesh filename="package://hospital_robot/meshes/montechargeR.stl" />
            </geometry>
        </collision>

        <visual>
            <origin xyz="0 0 0" rpy="3.14 0 0" />
            <geometry>
                <mesh
                filename="package://hospital_robot/meshes/montechargeR.stl" />
            </geometry>
            <material name="black"/>
        </visual>
    </link>

    <joint name="mchR_joint" type="prismatic">
    <origin xyz=" -0.04 0.17 0" rpy="0 0 0" />
    <parent link="sep1.2" />
    <child link="montechargeR" />
    <axis xyz="0 0 1" />
    <limit effort="1000.0" lower="0.35" upper="1.0" velocity="0.5"/>
  </joint>


  <link name="kjarL">
     <pose>0 0 0 0 0 0</pose>

        <collision>
            <origin xyz="0 0 0" rpy="0 0 1.57" />
            <geometry>
                <mesh filename="package://hospital_robot/meshes/kjar.stl" />
            </geometry>
        </collision>

        <visual>
            <origin xyz="0 0 0" rpy="0 0 1.57" />
            <geometry>
                <mesh
                filename="package://hospital_robot/meshes/kjar.stl" />
            </geometry>
            <material name="black"/>
        </visual>
    </link>

    <joint name="kjar_joint" type="prismatic">
    <origin xyz=" 0.51 -0.15 0.93" rpy="0 0 0" />
    <parent link="fix" />
    <child link="kjarL" />
    <axis xyz="0 1 0" />
    <limit effort="100.0" lower="0.1" upper="0.3" velocity="0.5"/>
  </joint>

  <link name="kjarR">
     <pose>0 0 0 0 0 0</pose>

        <collision>
            <origin xyz="0 0 0" rpy="0 0 -1.57" />
            <geometry>
                <mesh filename="package://hospital_robot/meshes/kjar.stl" />
            </geometry>
        </collision>

        <visual>
            <origin xyz="0 0 0" rpy="0 0 -1.57" />
            <geometry>
                <mesh
                filename="package://hospital_robot/meshes/kjar.stl" />
            </geometry>
            <material name="black"/>
        </visual>
    </link>

    <joint name="kjarR_joint" type="prismatic">
    <origin xyz=" 0.40 -0.24 0.93" rpy="0 0 0" />
    <parent link="fix" />
    <child link="kjarR" />
    <axis xyz="0 1 0" />
    <limit effort="100.0" lower="0.1" upper="0.3" velocity="0.5"/>
  </joint>

  <link name="plat">
     <pose>0 0 0 0 0 0</pose>

        <collision>
            <origin xyz="0 0 0" rpy="3.14 0 1.57" />
            <geometry>
                <mesh filename="package://hospital_robot/meshes/plateau.stl" />
            </geometry>
        </collision>

        <visual>
            <origin xyz="0 0 0" rpy="3.14 0 1.57" />
            <geometry>
                <mesh
                filename="package://hospital_robot/meshes/plateau.stl" />
            </geometry>
            <material name="argent"/>
        </visual>
    </link>

    <joint name="plat_joint" type="fixed">
    <origin xyz="0.06 0.14 0.06 " rpy="0 0 0" />
    <parent link="montechargeR" />
    <child link="plat" />
    <axis xyz="0 0 0" />
  </joint>

  <link name="bottle">
     <pose>0 0 0 0 0 0</pose>

        <collision>
            <origin xyz="0 0 0" rpy="0 0 0" />
            <geometry>
                <mesh filename="package://hospital_robot/meshes/bottle.stl" />
            </geometry>
        </collision>

        <visual>
            <origin xyz="0 0 0" rpy="0 0 0" />
            <geometry>
                <mesh
                filename="package://hospital_robot/meshes/bottle.stl" />
            </geometry>
            <material name="blue"/>
        </visual>
    </link>

    <joint name="bottle_joint" type="fixed">
    <origin xyz="0.23 0.15 0 " rpy="0 0 0" />
    <parent link="montechargeR" />
    <child link="bottle" />
    <axis xyz="0 0 0" />
  </joint>

  <link name="porteL">
     <pose>0 0 0 0 0 0</pose>

        <collision>
            <origin xyz="0 0 0" rpy="0 -1.57 1.57" />
            <geometry>
                <mesh filename="package://hospital_robot/meshes/porte.stl" />
            </geometry>
        </collision>

        <visual>
            <origin xyz="0 0 0" rpy="0 -1.57 1.57" />
            <geometry>
                <mesh
                filename="package://hospital_robot/meshes/porte.stl" />
            </geometry>
            <material name="silverT"/>
        </visual>
    </link>

    <joint name="porteL_joint" type="fixed">
    <origin xyz="0.395 0.305 0.01 " rpy="0 0 0" />
    <parent link="fix" />
    <child link="porteL" />
    <axis xyz="0 0 0" />
  </joint>

  <link name="porteR">
     <pose>0 0 0 0 0 0</pose>

        <collision>
            <origin xyz="0 0 0" rpy="0 -1.57 1.57" />
            <geometry>
                <mesh filename="package://hospital_robot/meshes/porte.stl" />
            </geometry>
        </collision>

        <visual>
            <origin xyz="0 0 0" rpy="0 -1.57 1.57" />
            <geometry>
                <mesh
                filename="package://hospital_robot/meshes/porte.stl" />
            </geometry>
            <material name="silverT"/>
        </visual>
    </link>

    <joint name="porteR_joint" type="fixed">
    <origin xyz="0.395 -0.305 0.01 " rpy="0 0 0" />
    <parent link="fix" />
    <child link="porteR" />
    <axis xyz="0 0 0" />
  </joint>

  <link name="yedL">
     <pose>0 0 0 0 0 0</pose>

        <collision>
            <origin xyz="0 0 0" rpy="0 0 0" />
            <geometry>
                <mesh filename="package://hospital_robot/meshes/yed.stl" />
            </geometry>
        </collision>

        <visual>
            <origin xyz="0 0 0" rpy="0 0 0" />
            <geometry>
                <mesh
                filename="package://hospital_robot/meshes/yed.stl" />
            </geometry>
            <material name="black"/>
        </visual>
    </link>

    <joint name="yedL_joint" type="fixed">
    <origin xyz="0.35 0.31 0.63  " rpy="0 0 0" />
    <parent link="fix" />
    <child link="yedL" />
    <axis xyz="0 0 0" />
  </joint>

  <link name="yedR">
     <pose>0 0 0 0 0 0</pose>

        <collision>
            <origin xyz="0 0 0" rpy="0 0 3.14" />
            <geometry>
                <mesh filename="package://hospital_robot/meshes/yed.stl" />
            </geometry>
        </collision>

        <visual>
            <origin xyz="0 0 0" rpy="0 0 3.14" />
            <geometry>
                <mesh
                filename="package://hospital_robot/meshes/yed.stl" />
            </geometry>
            <material name="black"/>
        </visual>
    </link>

    <joint name="yedR_joint" type="fixed">
    <origin xyz="0.36 -0.31 0.63  " rpy="0 0 0" />
    <parent link="fix" />
    <child link="yedR" />
    <axis xyz="0 0 0" />
  </joint>

  <link name="yedF">
     <pose>0 0 0 0 0 0</pose>

        <collision>
            <origin xyz="0 0 0" rpy="0 0 -1.57" />
            <geometry>
                <mesh filename="package://hospital_robot/meshes/yed.stl" />
            </geometry>
        </collision>

        <visual>
            <origin xyz="0 0 0" rpy="0 0 -1.57" />
            <geometry>
                <mesh
                filename="package://hospital_robot/meshes/yed.stl" />
            </geometry>
            <material name="black"/>
        </visual>
    </link>

    <joint name="yedF_joint" type="fixed">
    <origin xyz="0.615 0.01 0.63  " rpy="0 0 0" />
    <parent link="fix" />
    <child link="yedF" />
    <axis xyz="0 0 0" />
  </joint>

  <link name="gjouraL">
     <pose>0 0 0 0 0 0</pose>

        <collision>
            <origin xyz="0 0 0" rpy="0 0 1.57" />
            <geometry>
                <mesh filename="package://hospital_robot/meshes/9joura.stl" />
            </geometry>
        </collision>

        <visual>
            <origin xyz="0 0 0" rpy="0 0 1.57" />
            <geometry>
                <mesh
                filename="package://hospital_robot/meshes/9joura.stl" />
            </geometry>
            <material name="black"/>
        </visual>
    </link>

    <joint name="kjouraL_joint" type="fixed">
    <origin xyz="0.50 0.04 0.14  " rpy="0 0 0" />
    <parent link="fix" />
    <child link="gjouraL" />
    <axis xyz="0 0 0" />
  </joint>

  <link name="gjouraR">
     <pose>0 0 0 0 0 0</pose>

        <collision>
            <origin xyz="0 0 0" rpy="0 0 -1.57" />
            <geometry>
                <mesh filename="package://hospital_robot/meshes/9joura.stl" />
            </geometry>
        </collision>

        <visual>
            <origin xyz="0 0 0" rpy="0 0 -1.57" />
            <geometry>
                <mesh
                filename="package://hospital_robot/meshes/9joura.stl" />
            </geometry>
            <material name="black"/>
        </visual>
    </link>

    <joint name="kjouraR_joint" type="fixed">
    <origin xyz="0.40 -0.04 0.14  " rpy="0 0 0" />
    <parent link="fix" />
    <child link="gjouraR" />
    <axis xyz="0 0 0" />
  </joint>

  <link name="liaison">
     <pose>0 0 0 0 0 0</pose>

        <collision>
            <origin xyz="0 0 0" rpy="1.57 0 0" />
            <geometry>
                <mesh filename="package://hospital_robot/meshes/liaison.stl" />
            </geometry>
        </collision>

        <visual>
            <origin xyz="0 0 0" rpy="1.57 0 0" />
            <geometry>
                <mesh
                filename="package://hospital_robot/meshes/liaison.stl" />
            </geometry>
            <material name="cyan"/>
        </visual>
    </link>

    <joint name="liaison_joint" type="fixed">
    <origin xyz="-0.05 0.3 -0.113  " rpy="0 0 0" />
    <parent link="fix" />
    <child link="liaison" />
    <axis xyz="0 0 0" />
  </joint>

</robot>