<?xml version="1.0"?>
<robot name="robot" xmlns:xacro="http://www.ros.org/wiki/xacro">
     <material name="black">
        <color rgba="0.0 0.0 0.0 1.0" />
    </material>
    <material name="navy">
        <color rgba="0.0 0.0 128.0 1.0" />
    </material>
    <material name="cyan">
        <color rgba="0.0 255.0 255.0 1.0" />
    </material>
    <material name="silver">
        <color rgba="150.0 150.0 150.0 1.0" />
    </material>
    <material name="silverT">
        <color rgba="150.0 150.0 150.0 0.7" />
    </material>
    <material name="argent">
        <color rgba="206.0 206.0 206.0 1.0" />
    </material>
    <material name="red">
        <color rgba="255.0 0.0  0.0 1.0" />
    </material>
    <material name="blue">
        <color rgba="0.0 0.0  255.0 1.0" />
    </material>
    
  <link name="fix">
        <inertial>
            <origin xyz="0 0 0" rpy="0 0 0" />
            <mass value="40" />
            <inertia
                ixx="0.732368148523831"
                ixy="1.11340514515552E-06"
                ixz="2.11680638683535E-18"
                iyy="0.677204899068401"
                iyz="-2.63878968453045E-08"
                izz="1.4091545109818" />
            </inertial>

        <collision>
            <origin xyz="0 0 0.3" rpy="1.57 0 0" />
            <geometry>
                <mesh filename="package://hospital_robot/meshes/fix.dae" />
            </geometry>
        </collision>

        <visual>
            <origin xyz="0 0 0.3" rpy="1.57 0 0" />
            <geometry>
                <mesh
                filename="package://hospital_robot/meshes/fix.dae" />
            </geometry>
        </visual>
    </link>

    <link name="lampe">
        <inertial>
            <origin xyz="0 0 0" rpy="0 0 0" />
            <mass value="0.2" />
            <inertia
                ixx="0.732368148523831"
                ixy="1.11340514515552E-06"
                ixz="2.11680638683535E-18"
                iyy="0.677204899068401"
                iyz="-2.63878968453045E-08"
                izz="1.4091545109818" />
            </inertial>

        <collision>
            <origin xyz="0 0 0" rpy="0 0 1.57" />
            <geometry>
                <mesh filename="package://hospital_robot/meshes/lampe.dae" />
            </geometry>
        </collision>

        <visual>
            <origin xyz="0 0 0" rpy="0 0 1.57" />
            <geometry>
                <mesh
                filename="package://hospital_robot/meshes/lampe.dae" />
            </geometry>
        </visual>
    </link>

  <joint name="lampe_joint" type="fixed">
    <origin xyz="0.2 -0.05 1.31" rpy="0 0 0" />
    <parent link="fix" />
    <child link="lampe" />
    <axis xyz="0 0 0" />
  </joint>


  <link name="sep1">
        <collision>
            <origin xyz="0 0 0" rpy="0 0 3.14" />
            <geometry>
                <mesh filename="package://hospital_robot/meshes/sepcomplex.dae" />
            </geometry>
        </collision>

        <visual>
            <origin xyz="0 0 0" rpy="0 0 3.14" />
            <geometry>
                <mesh
                filename="package://hospital_robot/meshes/sepcomplex.dae" />
            </geometry>
        </visual>
    </link>

    <joint name="sep1_joint" type="fixed">
    <origin xyz="0.345 0.21 0.31" rpy="0 0 0" />
    <parent link="fix" />
    <child link="sep1" />
    <axis xyz="0 0 0" />
  </joint>

  <link name="sep2">
        <collision>
            <origin xyz="0 0 0" rpy="0 0 1.57" />
            <geometry>
                <mesh filename="package://hospital_robot/meshes/sep_simple.dae" />
            </geometry>
        </collision>

        <visual>
            <origin xyz="0 0 0" rpy="0 0 1.57" />
            <geometry>
                <mesh
                filename="package://hospital_robot/meshes/sep_simple.dae" />
            </geometry>
        </visual>
    </link>

    <joint name="sep2_joint" type="fixed">
    <origin xyz="0.25 0.15 0.31" rpy="0 0 0" />
    <parent link="fix" />
    <child link="sep2" />
    <axis xyz="0 0 0" />
  </joint>

  <link name="sep1.2">
        <collision>
            <origin xyz="0 0 0" rpy="0 0 0" />
            <geometry>
                <mesh filename="package://hospital_robot/meshes/sepcomplex.dae" />
            </geometry>
        </collision>

        <visual>
            <origin xyz="0 0 0" rpy="0 0 0" />
            <geometry>
                <mesh
                filename="package://hospital_robot/meshes/sepcomplex.dae" />
            </geometry>
        </visual>
    </link>

    <joint name="sep1.2_joint" type="fixed">
    <origin xyz="0.07 -0.21 0.31" rpy="0 0 0" />
    <parent link="fix" />
    <child link="sep1.2" />
    <axis xyz="0 0 0" />
  </joint>

  <link name="sep2.2">
        <collision>
            <origin xyz="0 0 0" rpy="0 0 1.57" />
            <geometry>
                <mesh filename="package://hospital_robot/meshes/sep_simple.dae" />
            </geometry>
        </collision>

        <visual>
            <origin xyz="0 0 0" rpy="0 0 1.57" />
            <geometry>
                <mesh
                filename="package://hospital_robot/meshes/sep_simple.dae" />
            </geometry>
        </visual>
    </link>

    <joint name="sep2.2_joint" type="fixed">
    <origin xyz="0.255 -0.28 0.31" rpy="0 0 0" />
    <parent link="fix" />
    <child link="sep2.2" />
    <axis xyz="0 0 0" />
  </joint>

  <link name="montechargeL">
        <collision>
            <origin xyz="0 0 0" rpy="0 0 0" />
            <geometry>
                <mesh filename="package://hospital_robot/meshes/monteChargeL.stl" />
            </geometry>
        </collision>

        <visual>
            <origin xyz="0 0 0" rpy="0 0 0" />
            <geometry>
                <mesh
                filename="package://hospital_robot/meshes/monteChargeL.stl" />
            </geometry>
            <material name="black"/>
        </visual>
    </link>

    <joint name="mchL_joint" type="prismatic">
    <origin xyz="-0.315 -0.17 0" rpy="0 0 0" />
    <parent link="sep1" />
    <child link="montechargeL" />
    <axis xyz="0 0 1" />
    <limit effort="1000.0" lower="0.2" upper="0.89" velocity="0.5"/>
  </joint>

  <link name="montechargeR">
        <collision>
            <origin xyz="0 0 0" rpy="3.14 0 0" />
            <geometry>
                <mesh filename="package://hospital_robot/meshes/montechargeR.stl" />
            </geometry>
        </collision>

        <visual>
            <origin xyz="0 0 0" rpy="3.14 0 0" />
            <geometry>
                <mesh
                filename="package://hospital_robot/meshes/montechargeR.stl" />
            </geometry>
            <material name="black"/>
        </visual>
    </link>

    <joint name="mchR_joint" type="prismatic">
    <origin xyz=" -0.04 0.17 0" rpy="0 0 0" />
    <parent link="sep1.2" />
    <child link="montechargeR" />
    <axis xyz="0 0 1" />
    <limit effort="1000.0" lower="0.2" upper="0.89" velocity="0.5"/>
  </joint>


  <link name="kjarL">
        <collision>
            <origin xyz="0 0 0" rpy="0 0 1.57" />
            <geometry>
                <mesh filename="package://hospital_robot/meshes/kjar.dae" />
            </geometry>
        </collision>

        <visual>
            <origin xyz="0 0 0" rpy="0 0 1.57" />
            <geometry>
                <mesh
                filename="package://hospital_robot/meshes/kjar.dae" />
            </geometry>
            <material name="black"/>
        </visual>
    </link>

    <joint name="kjar_joint" type="prismatic">
    <origin xyz=" 0.51 -0.15 1.237" rpy="0 0 0" />
    <parent link="fix" />
    <child link="kjarL" />
    <axis xyz="0 1 0" />
    <limit effort="100.0" lower="0.001" upper="0.4" velocity="0.5"/>
  </joint>

  <link name="kjarR">
        <collision>
            <origin xyz="0 0 0" rpy="0 0 -1.57" />
            <geometry>
                <mesh filename="package://hospital_robot/meshes/kjar.dae" />
            </geometry>
        </collision>

        <visual>
            <origin xyz="0 0 0" rpy="0 0 -1.57" />
            <geometry>
                <mesh
                filename="package://hospital_robot/meshes/kjar.dae" />
            </geometry>
            <material name="black"/>
        </visual>
    </link>

    <joint name="kjarR_joint" type="prismatic">
    <origin xyz=" 0.3965 -0.25 1.239" rpy="0 0 0" />
    <parent link="fix" />
    <child link="kjarR" />
    <axis xyz="0 1 0" />
    <limit effort="100.0" lower="0.001" upper="0.4" velocity="0.5"/>
  </joint>

  <link name="plat">
        <collision>
            <origin xyz="0 0 0" rpy="3.14 0 1.57" />
            <geometry>
                <mesh filename="package://hospital_robot/meshes/plateau.stl" />
            </geometry>
        </collision>

        <visual>
            <origin xyz="0 0 0" rpy="3.14 0 1.57" />
            <geometry>
                <mesh
                filename="package://hospital_robot/meshes/plateau.stl" />
            </geometry>
            <material name="argent"/>
        </visual>
    </link>

    <joint name="plat_joint" type="fixed">
    <origin xyz="0.06 0.05 0.06 " rpy="0 0 0" />
    <parent link="montechargeL" />
    <child link="plat" />
    <axis xyz="0 0 0" />
  </joint>

  <link name="bottle">
        <collision>
            <origin xyz="0 0 0" rpy="0 0 0" />
            <geometry>
                <mesh filename="package://hospital_robot/meshes/bottle.dae" />
            </geometry>
        </collision>

        <visual>
            <origin xyz="0 0 0" rpy="0 0 0" />
            <geometry>
                <mesh
                filename="package://hospital_robot/meshes/bottle.dae" />
            </geometry>
        </visual>
    </link>

    <joint name="bottle_joint" type="fixed">
    <origin xyz="0.23 0.05 0 " rpy="0 0 0" />
    <parent link="montechargeL" />
    <child link="bottle" />
    <axis xyz="0 0 0" />
  </joint>

  <link name="porteL">
        <collision>
            <origin xyz="0 0 0" rpy="0 -1.57 1.57" />
            <geometry>
                <mesh filename="package://hospital_robot/meshes/porte.stl" />
            </geometry>
        </collision>

        <visual>
            <origin xyz="0 0 0" rpy="0 -1.57 1.57" />
            <geometry>
                <mesh
                filename="package://hospital_robot/meshes/porte.stl" />
            </geometry>
            <material name="silverT"/>
        </visual>
    </link>

    <joint name="porteL_joint" type="fixed">
    <origin xyz="0.395 0.305 0.31 " rpy="0 0 0" />
    <parent link="fix" />
    <child link="porteL" />
    <axis xyz="0 0 0" />
  </joint>

  <link name="porteR">
        <collision>
            <origin xyz="0 0 0" rpy="0 -1.57 1.57" />
            <geometry>
                <mesh filename="package://hospital_robot/meshes/porte.stl" />
            </geometry>
        </collision>

        <visual>
            <origin xyz="0 0 0" rpy="0 -1.57 1.57" />
            <geometry>
                <mesh
                filename="package://hospital_robot/meshes/porte.stl" />
            </geometry>
            <material name="silverT"/>
        </visual>
    </link>

    <joint name="porteR_joint" type="fixed">
    <origin xyz="0.395 -0.305 0.31 " rpy="0 0 0" />
    <parent link="fix" />
    <child link="porteR" />
    <axis xyz="0 0 0" />
  </joint>

  <link name="yedL">
        <collision>
            <origin xyz="0 0 0" rpy="0 0 0" />
            <geometry>
                <mesh filename="package://hospital_robot/meshes/yed.stl" />
            </geometry>
        </collision>

        <visual>
            <origin xyz="0 0 0" rpy="0 0 0" />
            <geometry>
                <mesh
                filename="package://hospital_robot/meshes/yed.stl" />
            </geometry>
            <material name="black"/>
        </visual>
    </link>

    <joint name="yedL_joint" type="fixed">
    <origin xyz="0.35 0.31 0.93  " rpy="0 0 0" />
    <parent link="fix" />
    <child link="yedL" />
    <axis xyz="0 0 0" />
  </joint>

  <link name="yedR">
        <collision>
            <origin xyz="0 0 0" rpy="0 0 3.14" />
            <geometry>
                <mesh filename="package://hospital_robot/meshes/yed.stl" />
            </geometry>
        </collision>

        <visual>
            <origin xyz="0 0 0" rpy="0 0 3.14" />
            <geometry>
                <mesh
                filename="package://hospital_robot/meshes/yed.stl" />
            </geometry>
            <material name="black"/>
        </visual>
    </link>

    <joint name="yedR_joint" type="fixed">
    <origin xyz="0.36 -0.31 0.93  " rpy="0 0 0" />
    <parent link="fix" />
    <child link="yedR" />
    <axis xyz="0 0 0" />
  </joint>

  <link name="yedF">


        <collision>
            <origin xyz="0 0 0" rpy="0 0 -1.57" />
            <geometry>
                <mesh filename="package://hospital_robot/meshes/yed.stl" />
            </geometry>
        </collision>

        <visual>
            <origin xyz="0 0 0" rpy="0 0 -1.57" />
            <geometry>
                <mesh
                filename="package://hospital_robot/meshes/yed.stl" />
            </geometry>
            <material name="black"/>
        </visual>
    </link>

    <joint name="yedF_joint" type="fixed">
    <origin xyz="0.615 0.01 0.93  " rpy="0 0 0" />
    <parent link="fix" />
    <child link="yedF" />
    <axis xyz="0 0 0" />
  </joint>

  

  <link name="liaison">
        <collision>
            <origin xyz="0 0 0" rpy="1.57 0 0" />
            <geometry>
                <mesh filename="package://hospital_robot/meshes/liaison.dae" />
            </geometry>
        </collision>

        <visual>
            <origin xyz="0 0 0" rpy="1.57 0 0" />
            <geometry>
                <mesh
                filename="package://hospital_robot/meshes/liaison.dae" />
            </geometry>
        </visual>
    </link>

    <joint name="liaison_joint" type="fixed">
    <origin xyz="-0.05 0.3 0.187  " rpy="0 0 0" />
    <parent link="fix" />
    <child link="liaison" />
    <axis xyz="0 0 0" />
  </joint>

</robot>