<?xml version="1.0"?>
<robot name="penguin">

    <gazebo>
        <plugin name="gazebo_ros_control" filename="libgazebo_ros_control.so">
                <robotNamespace>/penguin</robotNamespace>
                <!--robotSimType>gazebo_ros_control/DefaultRobotHWSim</robotSimType-->
                <legacyModeNS>true</legacyModeNS>
        </plugin>
    </gazebo>

<!--links-->

    <link name="base_footprint">
        <origin xyz="0.0 0.0 0.007" rpy="0.0 0.0 1.57079632679"/>
    </link>
    <link name="base_link">
        <inertial>
            <origin xyz="0.0 0.0 0.007" rpy="0.0 0.0 1.57079632679"/>
            <mass value="0.160"/>
            <inertia ixx="0.0069858" ixy="0.00003788" ixz="-0.000743414" iyy="0.0070844" iyz="-0.00030005" izz="0.0008453"/>
        </inertial>
        <visual name="">
            <origin xyz="0.0 0.0 0.007" rpy="0.0 0.0 1.57079632679"/>
            <geometry>
                <mesh filename="package://penguin_description/models/meshes/base.dae" />   
            </geometry>
        </visual>
        <collision>
            <origin xyz="0.0 0.0 0.007" rpy="0.0 0.0 1.57079632679"/>
            <geometry>
                <!--cylinder radius="0.105" length="0.005"/-->
                <mesh filename="package://penguin_description/models/meshes/base.dae" />
            </geometry>
        </collision>
    </link>
    <link name="imu_link">
        <inertial>
            <mass value="0.001"/>
            <origin xyz="0 0 0" rpy="0 0 0"/>
            <inertia ixx="0.0001" ixy="0" ixz="0"
                    iyy="0.000001" iyz="0"
                    izz="0.0001"/>
        </inertial>
    </link>

    <link name="LW_link">
        <visual>
            <origin xyz="0.0 0.0 0.0" rpy="0.0 0.0 0.0"/>
            <geometry>
                <mesh filename="package://penguin_description/models/meshes/wheels.dae" />
            </geometry>
        </visual>
        <collision>
            <origin xyz="0.0 0.0 0.0" rpy="0.0 0.0 0.0"/>
            <geometry>
                <mesh filename="package://penguin_description/models/meshes/wheels.dae" />
            </geometry>
        </collision>
        <inertial>
            <origin xyz="0.0 0.0 0.0" rpy="0.0 0.0 0.0"/>
            <mass value="0.0264"/>
            <inertia ixx="0.000016739" ixy="0.0" ixz="0.0" iyy="0.000016739" iyz="0.0" izz="0.000020597"/>
        </inertial>
    </link>

    <link name="RW_link">
        <visual>
            <origin xyz="0.0 0.0 0.0" rpy="0.0 0.0 0.0"/>
            <geometry>
                <mesh filename="package://penguin_description/models/meshes/wheels.dae" />
            </geometry>
        </visual>
        <collision>
            <origin xyz="0.0 0.0 0.0" rpy="0.0 0.0 0.0"/>
            <geometry>
                <mesh filename="package://penguin_description/models/meshes/wheels.dae" />
            </geometry>
        </collision>
        <inertial>
            <origin xyz="0.0 0.0 0.0" rpy="0.0 0.0 0.0"/>
            <mass value="0.0264"/>
            <inertia ixx="0.000016739" ixy="0.0" ixz="0.0" iyy="0.000016739" iyz="0.0" izz="0.000020597"/>
        </inertial>
    </link>

    <link name="TCW_link">
        <visual>
            <origin xyz="0.0 0.0 0.00" rpy="0.0 0.0 0.0"/>
            <geometry>
                <mesh filename="package://penguin_description/models/meshes/caster_wheels.dae" />
            </geometry>
        </visual>
        <collision>
            <origin xyz="0.0 0.0 0.01" rpy="0.0 0.0 0.0"/>
            <geometry>
                <!--mesh filename="package://penguin_description/models/meshes/caster_wheels.dae"/-->
                <!--cylinder radius="0.001" length="0.02"/-->
                <sphere radius="0.01"/>
            </geometry>
        </collision>
        <inertial>
            <origin xyz="0.0 0.0 0.0" rpy="0.0 0.0 0.0"/>
            <mass value="0.02965"/>
            <inertia ixx="0.00000131067" ixy="0.0" ixz="0.0" iyy="0.00000191824" iyz="0.0" izz="0.00000139735"/>
        </inertial>
    </link>

    <link name="DCW_link">
        <visual>
            <origin xyz="0.0 0.0 0.00" rpy="0.0 0.0 0.0"/>
            <geometry>
                <mesh filename="package://penguin_description/models/meshes/caster_wheels.dae" />
            </geometry>
        </visual>
        <collision>
            <origin xyz="0.0 0.0 0.01" rpy="0.0 0.0 0.0"/>
            <geometry>
                <!--mesh filename="package://penguin_description/models/meshes/caster_wheels.dae"/-->
                <!--cylinder radius="0.001" length="0.02"/-->
                <sphere radius="0.01"/>
            </geometry>
        </collision>
        <inertial>
            <origin xyz="0.0 0.0 0.0" rpy="0.0 0.0 0.0"/>
            <mass value="0.02965"/>
            <inertia ixx="0.00000131067" ixy="0.0" ixz="0.0" iyy="0.00000191824" iyz="0.0" izz="0.00000139735"/>
        </inertial>
    </link>
    <link name="upper_base_link">
        <visual name="">
            <origin xyz="0.0 0.0 0.0" rpy="0.0 0.0 0.0"/>
            <geometry>
                <mesh filename="package://penguin_description/models/meshes/upper_base.dae"/>
            </geometry>
        </visual>
        <inertial>
            <origin xyz="0.0 0.0 0.0" rpy="0.0 0.0 0.0"/>
            <mass value="1.51143"/>
            <inertia ixx="0.172784748" ixy="0.000573265" ixz="-0.01351310072" iyy="0.0174117895" iyz="-0.007081193" izz="0.00756976136"/>
        </inertial>
        <collision>
            <origin xyz="0.0 0.0 0.00" rpy="0.0 0.0 0.0"/>
            <geometry>
                <mesh filename="package://penguin_description/models/meshes/upper_base.dae" />
            </geometry>
        </collision>
    </link>
    <link name="kinect_link">
        <visual >
            <origin xyz="0.0 0.0 0.0" rpy="0.0 0.0 1.5707"/>
            <geometry>
                <mesh filename="package://penguin_description/models/meshes/kinect.dae" />
            </geometry>
        </visual>
        <collision>
            <origin xyz="0.0 0.0 0.0" rpy="0 0 1.5707"/>
  	        <geometry>
  	            <box size="0.07271 0.27794 0.073"/>
  	        </geometry>
  	    </collision>
        <inertial>
            <mass value="0.564" />
            <origin xyz="0 0 0" />
            <inertia ixx="0.003881243" ixy="0.0" ixz="0.0"
                 iyy="0.000498940" iyz="0.0"
                 izz="0.003879257" />
        </inertial>
    </link>

<!--joints-->
    <joint name="base_footprint_joint" type="fixed">
        <origin xyz="0.0 0.0 0.0" rpy="0.0 0.0 0.0"/>
        <parent link="base_footprint"/>
        <child link="base_link"/>
    </joint>
    <joint name="base_imu_joint" type="fixed">
        <axis xyz="0 1 0"/>
        <origin xyz="0.0 0.0 0.0" rpy="0.0 0.0 0.0"/>
        <parent link="base_link"/>
        <child link="imu_link"/>
    </joint>
    <joint name="LW_base_joint" type="continuous">
        <origin xyz="-0.004 0.08  0.0314" rpy="0.0 0.0 3.1404"/>
        <parent link="base_link"/>
        <child link="LW_link"/>
        <axis xyz="0.0 -1 0.0"/>
        <limit effort="100" velocity="100"/>
    </joint>
    <joint name="RW_base_joint" type="continuous">
        <origin xyz="-0.004 -0.08  0.0314" rpy="0.0 0.0 0.0"/>
        <parent link="base_link"/>
        <child link="RW_link"/>
        <axis xyz="0.0 1 0.0"/>
        <limit effort="100" velocity="100"/>   
    </joint>
    <joint name="TCW_base_joint" type="fixed">
        <origin xyz="-0.092 0.0  0.000" rpy="0.0 0.0 1.57079632679"/>
        <parent link="base_link"/>
        <child link="TCW_link"/>
    </joint>
    <joint name="DCW_base_joint" type="fixed">
        <origin xyz="0.085 0.0  0.000" rpy="0.0 0.0 1.57079632679"/>
        <parent link="base_link"/>
        <child link="DCW_link"/>
    </joint>
    <joint name="upper_base_joint" type="fixed">
        <origin xyz="-0.004 0.0  0.005" rpy="0.0 0.0 1.57079632679"/>
        <parent link="base_link"/>
        <child link="upper_base_link"/>
    </joint>
    <joint name="kinect_base_joint" type="fixed">
        <origin xyz="0.0 0.0 0.2" rpy="0.0 0.0 0.0"/>
        <parent link="camera_rgb_frame"/>
        <child link="kinect_link"/>
    </joint>
<!--friction and stiffness-->
      <gazebo reference="LW_link">
	    <mu1>20000000000.0</mu1>
	    <mu2>20000000000.0</mu2>
	    <kp>1000000.0</kp>
	    <kd>1.0</kd>
	  </gazebo>
	
	  <gazebo reference="RW_link">
	    <mu1>20000000000.0</mu1>
	    <mu2>20000000000.0</mu2>
	    <kp>1000000.0</kp>
	    <kd>1.0</kd>
	  </gazebo>
	  
	  <gazebo reference="TCW_link">
	    <mu1>0.0</mu1>
	    <mu2>0.0</mu2>
	    <kp>1000000.0</kp>
	    <kd>100.0</kd>
	  </gazebo>
	  
	  <gazebo reference="DCW_link">
	    <mu1>0.0</mu1>
	    <mu2>0.0</mu2>
	    <kp>1000000.0</kp>
	    <kd>100.0</kd>
	  </gazebo>

<!--transmissions-->
    <transmission name="left_wheel_transmission">
        <type>transmission_interface/SimpleTransmission</type>
        <joint name="LW_base_joint">
            <hardwareInterface>hardware_interface/VelocityJointInterface</hardwareInterface>  
        </joint>
        <actuator name="left_wheel_actuator">
            <mechanicalReduction>7</mechanicalReduction>
            <hardwareInterface>hardware_interface/VelocityJointInterface</hardwareInterface>
        </actuator>
    </transmission>
    
    <transmission name="right_wheel_transmission">
        <type>transmission_interface/SimpleTransmission</type>
        <joint name="RW_base_joint">
            <hardwareInterface>hardware_interface/VelocityJointInterface</hardwareInterface>  
        </joint>
        <actuator name="right_wheel_actuator">
            <mechanicalReduction>7</mechanicalReduction>
            <hardwareInterface>hardware_interface/VelocityJointInterface</hardwareInterface>
        </actuator>
    </transmission>
<!--sensors-->
    <gazebo reference="kinect_link">  
      <sensor type="depth" name="camera">
        <always_on>true</always_on>
        <update_rate>20.0</update_rate>
        <camera>
          <horizontal_fov>1.04719755</horizontal_fov>
          <image>
            <format>R8G8B8</format>
            <width>640</width>
            <height>480</height>
          </image>
          <clip>
            <near>0.05</near>
            <far>8.0</far>
          </clip>
        </camera>
        <plugin name="kinect_camera_controller" filename="libgazebo_ros_openni_kinect.so">
          <cameraName>camera</cameraName>
          <alwaysOn>true</alwaysOn>
          <updateRate>10</updateRate>
          <imageTopicName>rgb/image_raw</imageTopicName>
          <depthImageTopicName>depth/image_raw</depthImageTopicName>
          <pointCloudTopicName>depth/points</pointCloudTopicName>
          <cameraInfoTopicName>rgb/camera_info</cameraInfoTopicName>
          <depthImageCameraInfoTopicName>depth/camera_info</depthImageCameraInfoTopicName>
          <frameName>camera_depth_optical_link</frameName>
          <baseline>0.1</baseline>
          <distortion_k1>0.0</distortion_k1>
          <distortion_k2>0.0</distortion_k2>
          <distortion_k3>0.0</distortion_k3>
          <distortion_t1>0.0</distortion_t1>
          <distortion_t2>0.0</distortion_t2>
          <pointCloudCutoff>0.4</pointCloudCutoff>
        </plugin>
      </sensor>
    </gazebo>
    <gazebo>
        <plugin name="gazebo_ros_imu_controller" filename="libgazebo_ros_imu.so">
            <!-- <robotNamespace></robotNamespace> -->
            <topicName>imu/data</topicName>
            <serviceName>imu/service</serviceName>
            <bodyName>base_link</bodyName>
            <gaussianNoise>0</gaussianNoise>
            <rpyOffsets>0 0 0</rpyOffsets>
            <updateRate>30.0</updateRate>
            <alwaysOn>true</alwaysOn>
            <gaussianNoise>0</gaussianNoise>
        </plugin>
    </gazebo>
<!--kinect frames--> 
 <joint name="camera_rgb_joint" type="fixed">
    <origin rpy="0 0 0" xyz="0 0 0"/>
    <parent link="base_link"/>
    <child link="camera_rgb_frame"/>
  </joint>
  <link name="camera_rgb_frame"/>
        
  
  <joint name="camera_rgb_optical_joint" type="fixed">
      <origin xyz="0 0 0" rpy="0 0 0.0" />
      <parent link="camera_rgb_frame" />
      <child link="camera_rgb_optical_frame" />
    </joint>
    <link name="camera_rgb_optical_frame"/>



    

    <joint name="camera_depth_joint" type="fixed">
	  <origin xyz="0 0.0 0" rpy="0 0 0" />
	  <parent link="camera_rgb_frame" />
	  <child link="camera_depth_frame" />
	</joint>
	<link name="camera_depth_frame"/>




    <joint name="camera_depth_optical_joint" type="fixed">
	  <origin xyz="0 0 0" rpy="0 0 0.0" />
	  <parent link="camera_depth_frame" />
	  <child link="camera_depth_optical_frame" />
	</joint>
	<link name="camera_depth_optical_frame"/>

</robot>
