<?xml version="1.0"?>
<robot name="penguin">
    <link name="base_link">
        <inertial>
            <origin xyz="0.0 0.0 0.007" rpy="0.0 0.0 0.0"/>
            <mass value="0.160"/>
            <inertia ixx="0.0069858" ixy="0.00003788" ixz="-0.000743414" iyy="0.0070844" iyz="-0.00030005" izz="0.0008453"/>
        </inertial>
        <visual name="">
            <origin xyz="0.0 0.0 0.007" rpy="0.0 0.0 0.0"/>
            <geometry>
                <mesh filename="package://penguin_description/models/meshes/base.dae" />   
            </geometry>
        </visual>
        <collision>
            <origin xyz="0.0 0.0 0.0095" rpy="0.0 0.0 0.0"/>
            <geometry>
                <cylinder radius="0.105" length="0.005"/>
            </geometry>
        </collision>
    </link>

    <link name="LW_link">
        <visual>
            <origin xyz="0.0 0.0 0.0" rpy="0.0 0.0 0.0"/>
            <geometry>
                <mesh filename="package://penguin_description/models/meshes/wheels.dae" />
            </geometry>
        </visual>
        <collision>
            <origin xyz="0.0 0.0 0.0" rpy="0.0 0.0 0.0"/>
            <geometry>
                <cylinder radius="0.0315" length="0.026"/>
            </geometry>
        </collision>
        <inertial>
            <origin xyz="0.0 0.0 0.0" rpy="0.0 0.0 0.0"/>
            <mass value="0.0264"/>
            <inertia ixx="0.000016739" ixy="0.0" ixz="0.0" iyy="0.000016739" iyz="0.0" izz="0.000020597"/>
        </inertial>
    </link>

    <link name="RW_link">
        <visual>
            <origin xyz="0.0 0.0 0.0" rpy="0.0 0.0 0.0"/>
            <geometry>
                <mesh filename="package://penguin_description/models/meshes/wheels.dae" />
            </geometry>
        </visual>
        <collision>
            <origin xyz="0.0 0.0 0.0" rpy="0.0 0.0 0.0"/>
            <geometry>
                <cylinder radius="0.0315" length="0.026"/>
            </geometry>
        </collision>
        <inertial>
            <origin xyz="0.0 0.0 0.0" rpy="0.0 0.0 0.0"/>
            <mass value="0.0264"/>
            <inertia ixx="0.000016739" ixy="0.0" ixz="0.0" iyy="0.000016739" iyz="0.0" izz="0.000020597"/>
        </inertial>
    </link>

    <link name="TCW_link">
        <visual>
            <origin xyz="0.0 0.0 0.0" rpy="0.0 0.0 0.0"/>
            <geometry>
                <mesh filename="package://penguin_description/models/meshes/caster_wheels.dae" />
            </geometry>
        </visual>
        <collision>
            <origin xyz="0.0 0.0 0.0" rpy="0.0 0.0 0.0"/>
            <geometry>
                <<mesh filename="package://penguin_description/models/meshes/caster_wheels.dae"/>
            </geometry>
        </collision>
        <inertial>
            <origin xyz="0.0 0.0 0.0" rpy="0.0 0.0 0.0"/>
            <mass value="0.02965"/>
            <inertia ixx="0.00000131067" ixy="0.0" ixz="0.0" iyy="0.00000191824" iyz="0.0" izz="0.00000139735"/>
        </inertial>
    </link>

    <link name="DCW_link">
        <visual>
            <origin xyz="0.0 0.0 0.0" rpy="0.0 0.0 0.0"/>
            <geometry>
                <mesh filename="package://penguin_description/models/meshes/caster_wheels.dae" />
            </geometry>
        </visual>
        <collision>
            <origin xyz="0.0 0.0 0.0" rpy="0.0 0.0 0.0"/>
            <geometry>
                <mesh filename="package://penguin_description/models/meshes/caster_wheels.dae"/>
            </geometry>
        </collision>
        <inertial>
            <origin xyz="0.0 0.0 0.0" rpy="0.0 0.0 0.0"/>
            <mass value="0.02965"/>
            <inertia ixx="0.00000131067" ixy="0.0" ixz="0.0" iyy="0.00000191824" iyz="0.0" izz="0.00000139735"/>
        </inertial>
    </link>

    <joint name="LW_base_joint" type="continuous">
        <origin xyz="0.08 0.003 0.0315" rpy="0.0 0.0 1.5707"/>
        <parent link="base_link"/>
        <child link="LW_link"/>
        <axis xyz="0.0 1 0.0"/>
    </joint>
    <joint name="RW_base_joint" type="continuous">
        <origin xyz="-0.08 0.003 0.0315" rpy="0.0 0.0 -1.5707"/>
        <parent link="base_link"/>
        <child link="RW_link"/>
        <axis xyz="0.0 1 0.0"/>
    </joint>
    <joint name="TCW_base_joint" type="fixed">
        <origin xyz="0.0 0.092 0.0" rpy="0.0 0.0 0.0"/>
        <parent link="base_link"/>
        <child link="TCW_link"/>
    </joint>
    <joint name="DCW_base_joint" type="fixed">
        <origin xyz="0.0 -0.085 0.0" rpy="0.0 0.0 0.0"/>
        <parent link="base_link"/>
        <child link="DCW_link"/>
    </joint>


    <gazebo reference="WL_link">
	    <mu1>1.0</mu1>
	    <mu2>1.0</mu2>
	    <kp>1000000.0</kp>
	    <kd>100.0</kd>
	    <minDepth>0.001</minDepth>
	    <maxVel>1.0</maxVel>
	  </gazebo>
	
	  <gazebo reference="WR_link">
	    <mu1>1.0</mu1>
	    <mu2>1.0</mu2>
	    <kp>1000000.0</kp>
	    <kd>100.0</kd>
	    <minDepth>0.001</minDepth>
	    <maxVel>1.0</maxVel>
	  </gazebo>
	  
	  <gazebo reference="TCW_link">
	    <mu1>0.0</mu1>
	    <mu2>0.0</mu2>
	    <kp>1000000.0</kp>
	    <kd>100.0</kd>
	    <minDepth>0.001</minDepth>
	    <maxVel>1.0</maxVel>
	  </gazebo>
	  
	  <gazebo reference="DCW_link">
	    <mu1>0.0</mu1>
	    <mu2>0.0</mu2>
	    <kp>1000000.0</kp>
	    <kd>100.0</kd>
	    <minDepth>0.001</minDepth>
	    <maxVel>1.0</maxVel>
	  </gazebo>

</robot>
